Workbook

Sheet DashBoard
C2: Financial Health Dashboard
C3: =Calculations!B15 -> Abu Dhabi National Hotels Company PJSC
D5: Overall Status
P6: Metrics Above Target | V6: =SUM(Calculations!I16:I17) -> 5 | AA6: Metrics Below Target | AG6: =Calculations!I15 -> 3
D7: =_xlfn.XLOOKUP(Calculations!$I$15,Calculations!$F$15:$F$23,Calculations!$E$15:$E$23) -> Critical
C11: =TEXT(Calculations!C21,"mmmm-yyy")&" Compared to "&TEXT(Calculations!C22,"mmmm-yyyy") -> December-2025 Compared to December-2024
C14: Sales | L14: Gross Margin | U14: Operating Margin | AD14: Net Margin
C15: =_xlfn.LET(_xlpm.val,_xlfn.XLOOKUP(C14,Calculations!$B$3:$B$10,Calculations!$C$3:$C$10,"something wrong",0), IF(ABS(_xlpm.val)>1.1, TEXT(_xlpm.val, "$#,##0;($#,##0)"), IF(AND(ABS(_xlpm.val)<1, ABS(_xlpm.val)>0.001), TEXT(_xlpm.val, "0.0%;(0.0%)"), TEXT(_xlpm.val, "0.00;(0.00)")))) -> $3,486,041 | H15: =_xlfn.LET(_xlpm.val, _xlfn.XLOOKUP(C14,Calculations!$B$3:$B$10,Calculations!$E$3:$E$10,"something wrong",0), IF(ABS(_xlpm.val)>1.1, TEXT(_xlpm.val, "$#,##0;($#,##0)"), IF(AND(ABS(_xlpm.val)<1, ABS(_xlpm.val)>0.001), TEXT(_xlpm.val, "0.0%;(0.0%)"), TEXT(_xlpm.val, "0.00;(0.00)")))) -> $598,428 | L15: =_xlfn.LET(_xlpm.val,_xlfn.XLOOKUP(L14,Calculations!$B$3:$B$10,Calculations!$C$3:$C$10,"something wrong",0), IF(ABS(_xlpm.val)>1.1, TEXT(_xlpm.val, "$#,##0;($#,##0)"), IF(AND(ABS(_xlpm.val)<1, ABS(_xlpm.val)>0.001), TEXT(_xlpm.val, "0.0%;(0.0%)"), TEXT(_xlpm.val, "0.00;(0.00)")))) -> 24.3% | Q15: =_xlfn.LET(_xlpm.val, _xlfn.XLOOKUP(L14,Calculations!$B$3:$B$10,Calculations!$E$3:$E$10,"something wrong",0), IF(ABS(_xlpm.val)>1.1, TEXT(_xlpm.val, "$#,##0;($#,##0)"), IF(AND(ABS(_xlpm.val)<1, ABS(_xlpm.val)>0.001), TEXT(_xlpm.val, "0.0%;(0.0%)"), TEXT(_xlpm.val, "0.00;(0.00)")))) -> 1.9% | U15: =_xlfn.LET(_xlpm.val,_xlfn.XLOOKUP(U14,Calculations!$B$3:$B$10,Calculations!$C$3:$C$10,"something wrong",0), IF(ABS(_xlpm.val)>1.1, TEXT(_xlpm.val, "$#,##0;($#,##0)"), IF(AND(ABS(_xlpm.val)<1, ABS(_xlpm.val)>0.001), TEXT(_xlpm.val, "0.0%;(0.0%)"), TEXT(_xlpm.val, "0.00;(0.00)")))) -> 35.3% | Z15: =_xlfn.LET(_xlpm.val, _xlfn.XLOOKUP(U14,Calculations!$B$3:$B$10,Calculations!$E$3:$E$10,"something wrong",0), IF(ABS(_xlpm.val)>1.1, TEXT(_xlpm.val, "$#,##0;($#,##0)"), IF(AND(ABS(_xlpm.val)<1, ABS(_xlpm.val)>0.001), TEXT(_xlpm.val, "0.0%;(0.0%)"), TEXT(_xlpm.val, "0.00;(0.00)")))) -> (14.3%) | AD15: =_xlfn.LET(_xlpm.val,_xlfn.XLOOKUP(AD14,Calculations!$B$3:$B$10,Calculations!$C$3:$C$10,"something wrong",0), IF(ABS(_xlpm.val)>1.1, TEXT(_xlpm.val, "$#,##0;($#,##0)"), IF(AND(ABS(_xlpm.val)<1, ABS(_xlpm.val)>0.001), TEXT(_xlpm.val, "0.0%;(0.0%)"), TEXT(_xlpm.val, "0.00;(0.00)")))) -> 32.9% | AI15: =_xlfn.LET(_xlpm.val, _xlfn.XLOOKUP(AD14,Calculations!$B$3:$B$10,Calculations!$E$3:$E$10,"something wrong",0), IF(ABS(_xlpm.val)>1.1, TEXT(_xlpm.val, "$#,##0;($#,##0)"), IF(AND(ABS(_xlpm.val)<1, ABS(_xlpm.val)>0.001), TEXT(_xlpm.val, "0.0%;(0.0%)"), TEXT(_xlpm.val, "0.00;(0.00)")))) -> (13.4%)
D19: Status: | F19: =_xlfn.XLOOKUP(C14,Calculations!$B$3:$B$10,Calculations!$H$3:$H$10,"something wrong",0) -> Excellent | M19: Status: | O19: =_xlfn.XLOOKUP(L14,Calculations!$B$3:$B$10,Calculations!$H$3:$H$10,"something wrong",0) -> Excellent | V19: Status: | X19: =_xlfn.XLOOKUP(U14,Calculations!$B$3:$B$10,Calculations!$H$3:$H$10,"something wrong",0) -> Critical | AE19: Status: | AG19: =_xlfn.XLOOKUP(AD14,Calculations!$B$3:$B$10,Calculations!$H$3:$H$10,"something wrong",0) -> Critical
C21: =_xlfn.XLOOKUP(C14,Calculations!$B$3:$B$10,Calculations!$I$3:$I$10,"something wrong",0) -> Total Revenue | L21: =_xlfn.XLOOKUP(L14,Calculations!$B$3:$B$10,Calculations!$I$3:$I$10,"something wrong",0) -> Gross Profit/Revenue | U21: =_xlfn.XLOOKUP(U14,Calculations!$B$3:$B$10,Calculations!$I$3:$I$10,"something wrong",0) -> Net Operating Income/Revenue | AD21: =_xlfn.XLOOKUP(AD14,Calculations!$B$3:$B$10,Calculations!$I$3:$I$10,"something wrong",0) -> Net Income/Revenue
C25: Working Capital | L25: Free Cash Flow | U25: Net Income | AD25: Cashflow From Operations
C26: =_xlfn.LET(_xlpm.val,_xlfn.XLOOKUP(C25,Calculations!$B$3:$B$10,Calculations!$C$3:$C$10,"something wrong",0), IF(ABS(_xlpm.val)>1.1, TEXT(_xlpm.val, "$#,##0;($#,##0)"), IF(AND(ABS(_xlpm.val)<1, ABS(_xlpm.val)>0.001), TEXT(_xlpm.val, "0.0%;(0.0%)"), TEXT(_xlpm.val, "0.00;(0.00)")))) -> $644,809 | H26: =_xlfn.LET(_xlpm.val, _xlfn.XLOOKUP(C25,Calculations!$B$3:$B$10,Calculations!$E$3:$E$10,"something wrong",0), IF(ABS(_xlpm.val)>1.1, TEXT(_xlpm.val, "$#,##0;($#,##0)"), IF(AND(ABS(_xlpm.val)<1, ABS(_xlpm.val)>0.001), TEXT(_xlpm.val, "0.0%;(0.0%)"), TEXT(_xlpm.val, "0.00;(0.00)")))) -> $65,348 | L26: =_xlfn.LET(_xlpm.val,_xlfn.XLOOKUP(L25,Calculations!$B$3:$B$10,Calculations!$C$3:$C$10,"something wrong",0), IF(ABS(_xlpm.val)>1.1, TEXT(_xlpm.val, "$#,##0;($#,##0)"), IF(AND(ABS(_xlpm.val)<1, ABS(_xlpm.val)>0.001), TEXT(_xlpm.val, "0.0%;(0.0%)"), TEXT(_xlpm.val, "0.00;(0.00)")))) -> $990,775 | Q26: =_xlfn.LET(_xlpm.val, _xlfn.XLOOKUP(L25,Calculations!$B$3:$B$10,Calculations!$E$3:$E$10,"something wrong",0), IF(ABS(_xlpm.val)>1.1, TEXT(_xlpm.val, "$#,##0;($#,##0)"), IF(AND(ABS(_xlpm.val)<1, ABS(_xlpm.val)>0.001), TEXT(_xlpm.val, "0.0%;(0.0%)"), TEXT(_xlpm.val, "0.00;(0.00)")))) -> $358,145 | U26: =_xlfn.LET(_xlpm.val,_xlfn.XLOOKUP(U25,Calculations!$B$3:$B$10,Calculations!$C$3:$C$10,"something wrong",0), IF(ABS(_xlpm.val)>1.1, TEXT(_xlpm.val, "$#,##0;($#,##0)"), IF(AND(ABS(_xlpm.val)<1, ABS(_xlpm.val)>0.001), TEXT(_xlpm.val, "0.0%;(0.0%)"), TEXT(_xlpm.val, "0.00;(0.00)")))) -> $1,145,865 | Z26: =_xlfn.LET(_xlpm.val, _xlfn.XLOOKUP(U25,Calculations!$B$3:$B$10,Calculations!$E$3:$E$10,"something wrong",0), IF(ABS(_xlpm.val)>1.1, TEXT(_xlpm.val, "$#,##0;($#,##0)"), IF(AND(ABS(_xlpm.val)<1, ABS(_xlpm.val)>0.001), TEXT(_xlpm.val, "0.0%;(0.0%)"), TEXT(_xlpm.val, "0.00;(0.00)")))) -> ($189,422) | AD26: =_xlfn.LET(_xlpm.val,_xlfn.XLOOKUP(AD25,Calculations!$B$3:$B$10,Calculations!$C$3:$C$10,"something wrong",0), IF(ABS(_xlpm.val)>1.1, TEXT(_xlpm.val, "$#,##0;($#,##0)"), IF(AND(ABS(_xlpm.val)<1, ABS(_xlpm.val)>0.001), TEXT(_xlpm.val, "0.0%;(0.0%)"), TEXT(_xlpm.val, "0.00;(0.00)")))) -> $769,132 | AI26: =_xlfn.LET(_xlpm.val, _xlfn.XLOOKUP(AD25,Calculations!$B$3:$B$10,Calculations!$E$3:$E$10,"something wrong",0), IF(ABS(_xlpm.val)>1.1, TEXT(_xlpm.val, "$#,##0;($#,##0)"), IF(AND(ABS(_xlpm.val)<1, ABS(_xlpm.val)>0.001), TEXT(_xlpm.val, "0.0%;(0.0%)"), TEXT(_xlpm.val, "0.00;(0.00)")))) -> $251,071
D30: Status: | F30: =_xlfn.XLOOKUP(C25,Calculations!$B$3:$B$10,Calculations!$H$3:$H$10,"something wrong",0) -> Excellent | M30: Status: | O30: =_xlfn.XLOOKUP(L25,Calculations!$B$3:$B$10,Calculations!$H$3:$H$10,"something wrong",0) -> Excellent | V30: Status: | X30: =_xlfn.XLOOKUP(U25,Calculations!$B$3:$B$10,Calculations!$H$3:$H$10,"something wrong",0) -> Critical | AE30: Status: | AG30: =_xlfn.XLOOKUP(AD25,Calculations!$B$3:$B$10,Calculations!$H$3:$H$10,"something wrong",0) -> Excellent
C32: =_xlfn.XLOOKUP(C25,Calculations!$B$3:$B$10,Calculations!$I$3:$I$10,"something wrong",0) -> Current Assets-Current Liability | L32: =_xlfn.XLOOKUP(L25,Calculations!$B$3:$B$10,Calculations!$I$3:$I$10,"something wrong",0) -> CF From Operation-Capex | U32: =_xlfn.XLOOKUP(U25,Calculations!$B$3:$B$10,Calculations!$I$3:$I$10,"something wrong",0) -> Total Income | AD32: =_xlfn.XLOOKUP(AD25,Calculations!$B$3:$B$10,Calculations!$I$3:$I$10,"something wrong",0) -> Cashflow From Operations

Sheet Income statement
B1: Abu Dhabi National Hotels Company PJSC
B3: Income Statement | C3: December 2025 | D3: December 2024
B4: Revenue from contracts with customers | C4: 3486041 | D4: 2887613
B5: Cost of sales | C5: -2637482 | D5: -2240075
B6: Gross profit | C6: 848559 | D6: 647538
B7: General and administrative expenses | C7: -213970 | D7: -186132
B8: Net impairment loss of financial assets | C8: -33075 | D8: -21623
B9: Fair value gain on financial assets at FVTPL | C9: 15573 | D9: 1788
B10: Gain on previously held equity interest in joint venture | C10: 13169 | D10: 916409
B11: Reversal of impairment losses | C11: 577535
B12: Other income | C12: 23124 | D12: 73801
B13: Operating profit | C13: 1230915 | D13: 1431781
B14: Finance income | C14: 21804 | D14: 4476
B15: Finance costs | C15: -90522 | D15: -114015
B16: Finance costs-net | C16: -68718 | D16: -109539
B17: Share of profit from associates | C17: 1806 | D17: 1941
B18: Share of profit from joint ventures | C18: 33572 | D18: 43607
B19: Profit before income tax | C19: 1197575 | D19: 1367790
B20: Income tax | C20: -51710 | D20: -32503
B21: Profit for the year | C21: 1145865 | D21: 1335287
B22: Attributable to: Equity holders of the parent | C22: 1084127 | D22: 1327096
B23: Non-controlling interests | C23: 61738 | D23: 8191

Sheet Balance Sheet
C2: Abu Dhabi National Hotels Company PJSC
C4: Balance Sheet | D4: 2025 | E4: 2024
C5: ASSETS
C6: Non-current assets
C7: Property and equipment | D7: 10654377 | E7: 9796986
C8: Right-of-use assets | D8: 16013 | E8: 33887
C9: Investment in associates | D9: 18179 | E9: 18176
C10: Investment in joint ventures | D10: 190423 | E10: 213971 | K10: 2025 | L10: 2024
C11: Financial asset at fair value through other comprehensive income | D11: 21179 | E11: 21179 | J11: Abu Dhabi National Hotels Company PJSC
C12: Franchise fee | D12: 666 | E12: 792 | J12: Consolidated statement of financial position
C13: Intangible assets | D13: 1126432 | E13: 1134489 | J13: Note
C14: Non-current assets | D14: =SUM(D7:D13) -> 12027269 | E14: =SUM(E7:E13) -> 11219480
C15: Current assets
C16: Inventories | D16: 27727 | E16: 26152
C17: Trade and other receivables | D17: 1040217 | E17: 857853
C18: Financial assets at FVTPL | D18: 317361 | E18: 401788
C19: Term deposits | E19: 403307
C20: Cash and cash equivalents | D20: 1095917 | E20: 571072
C21: Current assets | D21: =SUM(D16:D20) -> 2481222 | E21: =SUM(E16:E20) -> 2260172
C22: Total assets | D22: =SUM(D14,D21) -> 14508491 | E22: =SUM(E14,E21) -> 13479652
C24: EQUITY AND LIABILITIES
C25: EQUITY
C26: Share capital | D26: 1260000 | E26: 1260000
C27: Statutory and optional reserves | D27: 1000000 | E27: 1000000
C28: Own shares | D28: -53475 | E28: -114001
C29: Asset revaluation reserve | D29: 5739109 | E29: 5417347
C30: Retained earnings | D30: 2690397 | E30: 1978285
C31: Other reserve | D31: -5558 | E31: -
C32: Proposed dividends | D32: 378000 | E32: 567000
C33: Capital and reserves attributable to shareholders of the Parent | D33: =SUM(D26:D32) -> 11008473 | E33: =SUM(E26:E32) -> 10108631
C34: Non-controlling interests | D34: 496820 | E34: 452614
C35: Total equity | D35: =SUM(D33:D34) -> 11505293 | E35: =SUM(E33:E34) -> 10561245
C37: LIABILITIES
C38: Non-current liabilities
C39: Bank borrow ings | D39: 894350 | E39: 998451
C40: Provision for employees' end of service benefits | D40: 167809 | E40: 153505
C41: Deferred income tax liabilities | D41: 97761 | E41: 70162
C42: Lease liabilities | D42: 6865 | E42: 15578
C43: Non-current liabilities | D43: =SUM(D39:D42) -> 1166785 | E43: =SUM(E39:E42) -> 1237696
C44: Current liabilities
...

Sheet Cashflow
C1: Abu Dhabi National Hotels Company PJSC
C3: Cash flows from operating activities | D3: 2025 AED’000 | E3: 2024 AED’000
C4: Profit before income tax | D4: 1197575 | E4: 1367790
C5: Adjustments for:
C6: Depreciation of property and equipment | D6: 260618 | E6: 263788
C7: Depreciation of right-of-use assets | D7: 34715 | E7: 34361
C8: Share of profit from joint ventures | D8: -33572 | E8: -43607
C9: Share of profit from associates | D9: -1806 | E9: -1941
C10: Provision for impairment loss of financial assets | D10: 33075 | E10: 21623
C11: Reversal of impairment loss | D11: -577535 | E11: -
C12: Provision for employees’ end of service benefits | D12: 33344 | E12: 33939
C13: Loss/(gain) on disposal of property and equipment | D13: 8560 | E13: -67064
C14: Fair value gain on financial assets carried at fair value through profit or loss | D14: -15573 | E14: -1788
C15: Finance costs | D15: 90522 | E15: 114015
C16: Finance income | D16: -21804 | E16: -4476
C17: Gain on previously held equity interest in joint venture | D17: -13169 | E17: -916409
C18: Slow moving inventory provision | D18: 1224 | E18: 1235
C19: Gain on bargain purchase | D19: -4290 | E19: -
C20: Amortisation of intangible assets | D20: 41801 | E20: 30667
C21: Amortisation of franchise fee | D21: 126 | E21: 280
C22: Operating cash flows before payment of employees’s end of service benefits, income tax paid and changes in working capital | D22: 1033811 | E22: 832413
C23: Payment of employees’ end of service benefits | D23: -28991 | E23: -25570
C24: Income tax paid | D24: -42792 | E24: -
C25: Changes in working capital
C26: Inventories | D26: -2799 | E26: -3612
C27: Trade and other receivables | D27: -123632 | E27: 37580
C28: Trade and other payables | D28: -66465 | E28: -322750
C29: Net cash generated from operating activities | D29: 769132 | E29: 518061
C30: Cash flows from investing activities
C31: Purchase of property and equipment | D31: -221643 | E31: -114569
C32: Proceeds from disposal of property and equipment | D32: 12866 | E32: 40327
C33: Payment for acquisition of subsidiaries, net of cash acquired | D33: -2138 | E33: 76653
C34: Proceeds from disposal of financial assets at FVTPL | D34: 100000 | E34: -
C35: Payment for acquisition of a joint venture | D35: - | E35: -30000
C36: Dividends received from joint ventures and an associate | D36: 47015 | E36: 155684
C37: Term deposits placed with maturity of more than three months | D37: - | E37: -400000
C38: Purchase of financial assets at fair value through profit and loss | D38: - | E38: -400000
C39: Term deposits collected with maturity of more than three months | D39: 400000 | E39: -
C40: Finance income received | D40: 21,000 | E40: 1,169
C41: Net cash generated from/(used in) investing activities | D41: 357,100 | E41: -670736

Sheet Calculations
B2: Metric | C2: Current | D2: Comparison | E2: Variance | F2: Critical | G2: Good | H2: Status | I2: Explaination | J2: Variance %
B3: Sales | C3: ='Income statement'!C4 -> 3486041 | D3: ='Income statement'!D4 -> 2887613 | E3: =C3-D3 -> 598428 | F3: =D3*0.9 -> 2598851.7 | G3: =D3*1.05 -> 3031993.6 | H3: =IF(C3<=F3,"Critical",IF(C3<=G3,"Good","Excellent")) -> Excellent | I3: Total Revenue | J3: =E3/C3 -> 0.17166407
B4: Gross Margin | C4: ='Income statement'!C6/'Income statement'!C4 -> 0.24341624 | D4: ='Income statement'!D6/'Income statement'!D4 -> 0.22424681 | E4: =C4-D4 -> 0.019169433 | F4: =D4*0.9 -> 0.20182213 | G4: =D4*1.05 -> 0.23545915 | H4: =IF(C4<=F4,"Critical",IF(C4<=G4,"Good","Excellent")) -> Excellent | I4: Gross Profit/Revenue | J4: =E4/C4 -> 0.078751661
B5: Operating Margin | C5: ='Income statement'!C13/'Income statement'!C4 -> 0.35309826 | D5: ='Income statement'!D13/'Income statement'!D4 -> 0.49583549 | E5: =C5-D5 -> -0.14273723 | F5: =D5*0.9 -> 0.44625194 | G5: =D5*1.05 -> 0.52062726 | H5: =IF(C5<=F5,"Critical",IF(C5<=G5,"Good","Excellent")) -> Critical | I5: Net Operating Income/Revenue | J5: =E5/C5 -> -0.40424224
B6: Net Margin | C6: ='Income statement'!C21/'Income statement'!C4 -> 0.32870095 | D6: ='Income statement'!D21/'Income statement'!D4 -> 0.46241896 | E6: =C6-D6 -> -0.13371801 | F6: =D6*0.9 -> 0.41617706 | G6: =D6*1.05 -> 0.48553991 | H6: =IF(C6<=F6,"Critical",IF(C6<=G6,"Good","Excellent")) -> Critical | I6: Net Income/Revenue | J6: =E6/C6 -> -0.40680748
B7: Working Capital | C7: ='Balance Sheet'!D21-'Balance Sheet'!D49 -> 644809 | D7: ='Balance Sheet'!E21-'Balance Sheet'!E49 -> 579461 | E7: =C7-D7 -> 65348 | F7: =D7*0.9 -> 521514.9 | G7: =D7*1.05 -> 608434.05 | H7: =IF(C7<=F7,"Critical",IF(C7<=G7,"Good","Excellent")) -> Excellent | I7: Current Assets-Current Liability | J7: =E7/C7 -> 0.10134474
B8: Free Cash Flow | C8: =Cashflow!D29-Cashflow!D31 -> 990775 | D8: =Cashflow!E29-Cashflow!E31 -> 632630 | E8: =C8-D8 -> 358145 | F8: =D8*0.9 -> 569367 | G8: =D8*1.05 -> 664261.5 | H8: =IF(C8<=F8,"Critical",IF(C8<=G8,"Good","Excellent")) -> Excellent | I8: CF From Operation-Capex | J8: =E8/C8 -> 0.36147965
B9: Net Income | C9: ='Income statement'!C21 -> 1145865 | D9: ='Income statement'!D21 -> 1335287 | E9: =C9-D9 -> -189422 | F9: =D9*0.9 -> 1201758.3 | G9: =D9*1.05 -> 1402051.4 | H9: =IF(C9<=F9,"Critical",IF(C9<=G9,"Good","Excellent")) -> Critical | I9: Total Income | J9: =E9/C9 -> -0.16530918
B10: Cashflow From Operations | C10: =Cashflow!D29 -> 769132 | D10: =Cashflow!E29 -> 518061 | E10: =C10-D10 -> 251071 | F10: =D10*0.9 -> 466254.9 | G10: =D10*1.05 -> 543964.05 | H10: =IF(C10<=F10,"Critical",IF(C10<=G10,"Good","Excellent")) -> Excellent | I10: Cashflow From Operations | J10: =E10/C10 -> 0.32643421
L13: NOTE:
E14: Status | F14: Critical Count | H14: status | I14: Count | L14: FORMULA
B15: Abu Dhabi National Hotels Company PJSC | E15: Excellent | F15: 0 | H15: Critical | I15: =COUNTIFS($H$3:$H$10,H15) -> 3 | L15: LET(val, XLOOKUP(C14,Calculations!B3:B10,Calculations!C3:C10,0,0), IF(ABS(val)>1.1, TEXT(val, "$#,##0;($#,##0)"), IF(AND(ABS(val)<1, ABS(val)>0.001), TEXT(val, "0.0%;(0.0%)"), TEXT(val, "0.00;(0.00)"))))
E16: Good | F16: 1 | H16: Good | I16: =COUNTIFS($H$3:$H$10,H16) -> 0
E17: Good | F17: 2 | H17: Excellent | I17: =COUNTIFS($H$3:$H$10,H17) -> 5
E18: Critical | F18: 3
E19: Critical | F19: 4
B20: Title | C20: Period | E20: Critical | F20: 5
B21: Current Period | C21: 46022 | E21: Critical | F21: 6
B22: Comparison Period | C22: 45657 | E22: Critical | F22: 7
E23: Critical | F23: 8
L25: ADD THE CORRECT XLOOKUP
